[2024-04-23T12:46:24.783+0000] {taskinstance.py:1979} INFO - Dependencies all met for dep_context=non-requeueable deps ti=<TaskInstance: pipeline_eq.push_in_redis manual__2024-04-23T11:54:48.966898+00:00 map_index=31 [queued]>
[2024-04-23T12:46:24.793+0000] {taskinstance.py:1979} INFO - Dependencies all met for dep_context=requeueable deps ti=<TaskInstance: pipeline_eq.push_in_redis manual__2024-04-23T11:54:48.966898+00:00 map_index=31 [queued]>
[2024-04-23T12:46:24.794+0000] {taskinstance.py:2193} INFO - Starting attempt 1 of 1
[2024-04-23T12:46:24.808+0000] {taskinstance.py:2217} INFO - Executing <Mapped(_PythonDecoratedOperator): push_in_redis> on 2024-04-23 11:54:48.966898+00:00
[2024-04-23T12:46:24.813+0000] {standard_task_runner.py:60} INFO - Started process 157087 to run task
[2024-04-23T12:46:24.815+0000] {standard_task_runner.py:87} INFO - Running: ['airflow', 'tasks', 'run', 'pipeline_eq', 'push_in_redis', 'manual__2024-04-23T11:54:48.966898+00:00', '--job-id', '339', '--raw', '--subdir', 'DAGS_FOLDER/kbs/custom_dags/pipeline_eq.py', '--cfg-path', '/tmp/tmp15hbd12v', '--map-index', '31']
[2024-04-23T12:46:24.816+0000] {standard_task_runner.py:88} INFO - Job 339: Subtask push_in_redis
[2024-04-23T12:46:24.845+0000] {task_command.py:423} INFO - Running <TaskInstance: pipeline_eq.push_in_redis manual__2024-04-23T11:54:48.966898+00:00 map_index=31 [running]> on host datalab-yasmine
[2024-04-23T12:46:25.019+0000] {taskinstance.py:2513} INFO - Exporting env vars: AIRFLOW_CTX_DAG_OWNER='airflow' AIRFLOW_CTX_DAG_ID='pipeline_eq' AIRFLOW_CTX_TASK_ID='push_in_redis' AIRFLOW_CTX_EXECUTION_DATE='2024-04-23T11:54:48.966898+00:00' AIRFLOW_CTX_TRY_NUMBER='1' AIRFLOW_CTX_DAG_RUN_ID='manual__2024-04-23T11:54:48.966898+00:00'
[2024-04-23T12:46:25.020+0000] {pipeline_eq.py:90} INFO - start to push data in redis
[2024-04-23T12:46:26.538+0000] {connectionpool.py:874} WARNING - Retrying (Retry(total=4, connect=None, read=None, redirect=None, status=None)) after connection broken by 'RemoteDisconnected('Remote end closed connection without response')': /extracted?location=
[2024-04-23T12:46:28.372+0000] {connectionpool.py:874} WARNING - Retrying (Retry(total=3, connect=None, read=None, redirect=None, status=None)) after connection broken by 'RemoteDisconnected('Remote end closed connection without response')': /extracted?location=
[2024-04-23T12:46:29.977+0000] {taskinstance.py:2731} ERROR - Task failed with exception
Traceback (most recent call last):
  File "/home/yasmine/.local/share/virtualenvs/knowledge-base-siaap-WvBZnYs-/lib/python3.8/site-packages/airflow/models/taskinstance.py", line 444, in _execute_task
    result = _execute_callable(context=context, **execute_callable_kwargs)
  File "/home/yasmine/.local/share/virtualenvs/knowledge-base-siaap-WvBZnYs-/lib/python3.8/site-packages/airflow/models/taskinstance.py", line 414, in _execute_callable
    return execute_callable(context=context, **execute_callable_kwargs)
  File "/home/yasmine/.local/share/virtualenvs/knowledge-base-siaap-WvBZnYs-/lib/python3.8/site-packages/airflow/decorators/base.py", line 241, in execute
    return_value = super().execute(context)
  File "/home/yasmine/.local/share/virtualenvs/knowledge-base-siaap-WvBZnYs-/lib/python3.8/site-packages/airflow/operators/python.py", line 200, in execute
    return_value = self.execute_callable()
  File "/home/yasmine/.local/share/virtualenvs/knowledge-base-siaap-WvBZnYs-/lib/python3.8/site-packages/airflow/operators/python.py", line 217, in execute_callable
    return self.python_callable(*self.op_args, **self.op_kwargs)
  File "/home/yasmine/Documents/FREELANCE/knowledge-base-siaap/dags/kbs/custom_dags/pipeline_eq.py", line 95, in push_in_redis
    REDIS_CLIENT.json().set(key, path.Path.root_path(), data)
  File "/home/yasmine/.local/share/virtualenvs/knowledge-base-siaap-WvBZnYs-/lib/python3.8/site-packages/redis/commands/json/commands.py", line 255, in set
    return self.execute_command("JSON.SET", *pieces)
  File "/home/yasmine/.local/share/virtualenvs/knowledge-base-siaap-WvBZnYs-/lib/python3.8/site-packages/redis/client.py", line 543, in execute_command
    return conn.retry.call_with_retry(
  File "/home/yasmine/.local/share/virtualenvs/knowledge-base-siaap-WvBZnYs-/lib/python3.8/site-packages/redis/retry.py", line 46, in call_with_retry
    return do()
  File "/home/yasmine/.local/share/virtualenvs/knowledge-base-siaap-WvBZnYs-/lib/python3.8/site-packages/redis/client.py", line 544, in <lambda>
    lambda: self._send_command_parse_response(
  File "/home/yasmine/.local/share/virtualenvs/knowledge-base-siaap-WvBZnYs-/lib/python3.8/site-packages/redis/client.py", line 519, in _send_command_parse_response
    conn.send_command(*args)
  File "/home/yasmine/.local/share/virtualenvs/knowledge-base-siaap-WvBZnYs-/lib/python3.8/site-packages/redis/connection.py", line 477, in send_command
    self._command_packer.pack(*args),
  File "/home/yasmine/.local/share/virtualenvs/knowledge-base-siaap-WvBZnYs-/lib/python3.8/site-packages/redis/connection.py", line 96, in pack
    for arg in map(self.encode, args):
  File "/home/yasmine/.local/share/virtualenvs/knowledge-base-siaap-WvBZnYs-/lib/python3.8/site-packages/redis/_parsers/encoders.py", line 29, in encode
    raise DataError(
redis.exceptions.DataError: Invalid input of type: 'UUID'. Convert to a bytes, string, int or float first.
[2024-04-23T12:46:29.982+0000] {taskinstance.py:1149} INFO - Marking task as FAILED. dag_id=pipeline_eq, task_id=push_in_redis, map_index=31, execution_date=20240423T115448, start_date=20240423T124624, end_date=20240423T124629
[2024-04-23T12:46:29.995+0000] {standard_task_runner.py:107} ERROR - Failed to execute job 339 for task push_in_redis (Invalid input of type: 'UUID'. Convert to a bytes, string, int or float first.; 157087)
[2024-04-23T12:46:30.026+0000] {local_task_job_runner.py:234} INFO - Task exited with return code 1
[2024-04-23T12:46:30.034+0000] {taskinstance.py:3312} INFO - 0 downstream tasks scheduled from follow-on schedule check
