[2024-04-23T12:42:27.813+0000] {taskinstance.py:1979} INFO - Dependencies all met for dep_context=non-requeueable deps ti=<TaskInstance: pipeline_eq.push_in_redis manual__2024-04-23T11:54:48.966898+00:00 map_index=1 [queued]>
[2024-04-23T12:42:27.818+0000] {taskinstance.py:1979} INFO - Dependencies all met for dep_context=requeueable deps ti=<TaskInstance: pipeline_eq.push_in_redis manual__2024-04-23T11:54:48.966898+00:00 map_index=1 [queued]>
[2024-04-23T12:42:27.819+0000] {taskinstance.py:2193} INFO - Starting attempt 1 of 1
[2024-04-23T12:42:27.829+0000] {taskinstance.py:2217} INFO - Executing <Mapped(_PythonDecoratedOperator): push_in_redis> on 2024-04-23 11:54:48.966898+00:00
[2024-04-23T12:42:27.833+0000] {standard_task_runner.py:60} INFO - Started process 150710 to run task
[2024-04-23T12:42:27.835+0000] {standard_task_runner.py:87} INFO - Running: ['airflow', 'tasks', 'run', 'pipeline_eq', 'push_in_redis', 'manual__2024-04-23T11:54:48.966898+00:00', '--job-id', '293', '--raw', '--subdir', 'DAGS_FOLDER/kbs/custom_dags/pipeline_eq.py', '--cfg-path', '/tmp/tmptdypo629', '--map-index', '1']
[2024-04-23T12:42:27.836+0000] {standard_task_runner.py:88} INFO - Job 293: Subtask push_in_redis
[2024-04-23T12:42:27.860+0000] {task_command.py:423} INFO - Running <TaskInstance: pipeline_eq.push_in_redis manual__2024-04-23T11:54:48.966898+00:00 map_index=1 [running]> on host datalab-yasmine
[2024-04-23T12:42:28.017+0000] {taskinstance.py:2513} INFO - Exporting env vars: AIRFLOW_CTX_DAG_OWNER='airflow' AIRFLOW_CTX_DAG_ID='pipeline_eq' AIRFLOW_CTX_TASK_ID='push_in_redis' AIRFLOW_CTX_EXECUTION_DATE='2024-04-23T11:54:48.966898+00:00' AIRFLOW_CTX_TRY_NUMBER='1' AIRFLOW_CTX_DAG_RUN_ID='manual__2024-04-23T11:54:48.966898+00:00'
[2024-04-23T12:42:28.018+0000] {pipeline_eq.py:90} INFO - start to push data in redis
[2024-04-23T12:42:30.209+0000] {taskinstance.py:2731} ERROR - Task failed with exception
Traceback (most recent call last):
  File "/home/yasmine/.local/share/virtualenvs/knowledge-base-siaap-WvBZnYs-/lib/python3.8/site-packages/airflow/models/taskinstance.py", line 444, in _execute_task
    result = _execute_callable(context=context, **execute_callable_kwargs)
  File "/home/yasmine/.local/share/virtualenvs/knowledge-base-siaap-WvBZnYs-/lib/python3.8/site-packages/airflow/models/taskinstance.py", line 414, in _execute_callable
    return execute_callable(context=context, **execute_callable_kwargs)
  File "/home/yasmine/.local/share/virtualenvs/knowledge-base-siaap-WvBZnYs-/lib/python3.8/site-packages/airflow/decorators/base.py", line 241, in execute
    return_value = super().execute(context)
  File "/home/yasmine/.local/share/virtualenvs/knowledge-base-siaap-WvBZnYs-/lib/python3.8/site-packages/airflow/operators/python.py", line 200, in execute
    return_value = self.execute_callable()
  File "/home/yasmine/.local/share/virtualenvs/knowledge-base-siaap-WvBZnYs-/lib/python3.8/site-packages/airflow/operators/python.py", line 217, in execute_callable
    return self.python_callable(*self.op_args, **self.op_kwargs)
  File "/home/yasmine/Documents/FREELANCE/knowledge-base-siaap/dags/kbs/custom_dags/pipeline_eq.py", line 94, in push_in_redis
    key = uuid.UUID()
  File "/home/yasmine/.pyenv/versions/3.8.16/lib/python3.8/uuid.py", line 165, in __init__
    raise TypeError('one of the hex, bytes, bytes_le, fields, '
TypeError: one of the hex, bytes, bytes_le, fields, or int arguments must be given
[2024-04-23T12:42:30.213+0000] {taskinstance.py:1149} INFO - Marking task as FAILED. dag_id=pipeline_eq, task_id=push_in_redis, map_index=1, execution_date=20240423T115448, start_date=20240423T124227, end_date=20240423T124230
[2024-04-23T12:42:30.220+0000] {standard_task_runner.py:107} ERROR - Failed to execute job 293 for task push_in_redis (one of the hex, bytes, bytes_le, fields, or int arguments must be given; 150710)
[2024-04-23T12:42:30.255+0000] {local_task_job_runner.py:234} INFO - Task exited with return code 1
[2024-04-23T12:42:30.268+0000] {taskinstance.py:3312} INFO - 0 downstream tasks scheduled from follow-on schedule check
