[2024-04-23T12:43:02.715+0000] {taskinstance.py:1979} INFO - Dependencies all met for dep_context=non-requeueable deps ti=<TaskInstance: pipeline_eq.push_in_redis manual__2024-04-23T11:54:48.966898+00:00 map_index=7 [queued]>
[2024-04-23T12:43:02.720+0000] {taskinstance.py:1979} INFO - Dependencies all met for dep_context=requeueable deps ti=<TaskInstance: pipeline_eq.push_in_redis manual__2024-04-23T11:54:48.966898+00:00 map_index=7 [queued]>
[2024-04-23T12:43:02.721+0000] {taskinstance.py:2193} INFO - Starting attempt 1 of 1
[2024-04-23T12:43:02.736+0000] {taskinstance.py:2217} INFO - Executing <Mapped(_PythonDecoratedOperator): push_in_redis> on 2024-04-23 11:54:48.966898+00:00
[2024-04-23T12:43:02.740+0000] {standard_task_runner.py:60} INFO - Started process 151646 to run task
[2024-04-23T12:43:02.743+0000] {standard_task_runner.py:87} INFO - Running: ['airflow', 'tasks', 'run', 'pipeline_eq', 'push_in_redis', 'manual__2024-04-23T11:54:48.966898+00:00', '--job-id', '299', '--raw', '--subdir', 'DAGS_FOLDER/kbs/custom_dags/pipeline_eq.py', '--cfg-path', '/tmp/tmpw3cw8ui9', '--map-index', '7']
[2024-04-23T12:43:02.743+0000] {standard_task_runner.py:88} INFO - Job 299: Subtask push_in_redis
[2024-04-23T12:43:02.768+0000] {task_command.py:423} INFO - Running <TaskInstance: pipeline_eq.push_in_redis manual__2024-04-23T11:54:48.966898+00:00 map_index=7 [running]> on host datalab-yasmine
[2024-04-23T12:43:02.928+0000] {taskinstance.py:2513} INFO - Exporting env vars: AIRFLOW_CTX_DAG_OWNER='airflow' AIRFLOW_CTX_DAG_ID='pipeline_eq' AIRFLOW_CTX_TASK_ID='push_in_redis' AIRFLOW_CTX_EXECUTION_DATE='2024-04-23T11:54:48.966898+00:00' AIRFLOW_CTX_TRY_NUMBER='1' AIRFLOW_CTX_DAG_RUN_ID='manual__2024-04-23T11:54:48.966898+00:00'
[2024-04-23T12:43:02.929+0000] {pipeline_eq.py:90} INFO - start to push data in redis
[2024-04-23T12:43:07.069+0000] {connectionpool.py:874} WARNING - Retrying (Retry(total=4, connect=None, read=None, redirect=None, status=None)) after connection broken by 'RemoteDisconnected('Remote end closed connection without response')': /extracted?location=
[2024-04-23T12:43:08.709+0000] {taskinstance.py:2731} ERROR - Task failed with exception
Traceback (most recent call last):
  File "/home/yasmine/.local/share/virtualenvs/knowledge-base-siaap-WvBZnYs-/lib/python3.8/site-packages/airflow/models/taskinstance.py", line 444, in _execute_task
    result = _execute_callable(context=context, **execute_callable_kwargs)
  File "/home/yasmine/.local/share/virtualenvs/knowledge-base-siaap-WvBZnYs-/lib/python3.8/site-packages/airflow/models/taskinstance.py", line 414, in _execute_callable
    return execute_callable(context=context, **execute_callable_kwargs)
  File "/home/yasmine/.local/share/virtualenvs/knowledge-base-siaap-WvBZnYs-/lib/python3.8/site-packages/airflow/decorators/base.py", line 241, in execute
    return_value = super().execute(context)
  File "/home/yasmine/.local/share/virtualenvs/knowledge-base-siaap-WvBZnYs-/lib/python3.8/site-packages/airflow/operators/python.py", line 200, in execute
    return_value = self.execute_callable()
  File "/home/yasmine/.local/share/virtualenvs/knowledge-base-siaap-WvBZnYs-/lib/python3.8/site-packages/airflow/operators/python.py", line 217, in execute_callable
    return self.python_callable(*self.op_args, **self.op_kwargs)
  File "/home/yasmine/Documents/FREELANCE/knowledge-base-siaap/dags/kbs/custom_dags/pipeline_eq.py", line 94, in push_in_redis
    key = uuid.UUID('hex')
  File "/home/yasmine/.pyenv/versions/3.8.16/lib/python3.8/uuid.py", line 171, in __init__
    raise ValueError('badly formed hexadecimal UUID string')
ValueError: badly formed hexadecimal UUID string
[2024-04-23T12:43:08.713+0000] {taskinstance.py:1149} INFO - Marking task as FAILED. dag_id=pipeline_eq, task_id=push_in_redis, map_index=7, execution_date=20240423T115448, start_date=20240423T124302, end_date=20240423T124308
[2024-04-23T12:43:08.722+0000] {standard_task_runner.py:107} ERROR - Failed to execute job 299 for task push_in_redis (badly formed hexadecimal UUID string; 151646)
[2024-04-23T12:43:08.762+0000] {local_task_job_runner.py:234} INFO - Task exited with return code 1
[2024-04-23T12:43:08.770+0000] {taskinstance.py:3312} INFO - 0 downstream tasks scheduled from follow-on schedule check
