[2024-04-23T11:58:05.721+0000] {taskinstance.py:1979} INFO - Dependencies all met for dep_context=non-requeueable deps ti=<TaskInstance: pipeline_eq.read_equipements manual__2024-04-23T11:54:48.966898+00:00 [queued]>
[2024-04-23T11:58:05.727+0000] {taskinstance.py:1979} INFO - Dependencies all met for dep_context=requeueable deps ti=<TaskInstance: pipeline_eq.read_equipements manual__2024-04-23T11:54:48.966898+00:00 [queued]>
[2024-04-23T11:58:05.727+0000] {taskinstance.py:2193} INFO - Starting attempt 2 of 2
[2024-04-23T11:58:05.739+0000] {taskinstance.py:2217} INFO - Executing <Task(_PythonDecoratedOperator): read_equipements> on 2024-04-23 11:54:48.966898+00:00
[2024-04-23T11:58:05.744+0000] {standard_task_runner.py:60} INFO - Started process 112929 to run task
[2024-04-23T11:58:05.746+0000] {standard_task_runner.py:87} INFO - Running: ['airflow', 'tasks', 'run', 'pipeline_eq', 'read_equipements', 'manual__2024-04-23T11:54:48.966898+00:00', '--job-id', '283', '--raw', '--subdir', 'DAGS_FOLDER/kbs/custom_dags/pipeline_eq.py', '--cfg-path', '/tmp/tmpmm4dqs9d']
[2024-04-23T11:58:05.747+0000] {standard_task_runner.py:88} INFO - Job 283: Subtask read_equipements
[2024-04-23T11:58:05.774+0000] {task_command.py:423} INFO - Running <TaskInstance: pipeline_eq.read_equipements manual__2024-04-23T11:54:48.966898+00:00 [running]> on host datalab-yasmine
[2024-04-23T11:58:05.928+0000] {taskinstance.py:2513} INFO - Exporting env vars: AIRFLOW_CTX_DAG_OWNER='airflow' AIRFLOW_CTX_DAG_ID='pipeline_eq' AIRFLOW_CTX_TASK_ID='read_equipements' AIRFLOW_CTX_EXECUTION_DATE='2024-04-23T11:54:48.966898+00:00' AIRFLOW_CTX_TRY_NUMBER='2' AIRFLOW_CTX_DAG_RUN_ID='manual__2024-04-23T11:54:48.966898+00:00'
[2024-04-23T11:58:05.929+0000] {pipeline_eq.py:65} INFO - get date
[2024-04-23T11:58:05.929+0000] {rw.py:43} INFO - start to get objects in minio
[2024-04-23T11:58:05.929+0000] {rw.py:45} INFO - get objects
[2024-04-23T11:58:05.929+0000] {rw.py:48} INFO - get good objects
[2024-04-23T11:58:07.511+0000] {logging_mixin.py:188} INFO - {'start': '2024-04-23 11:54:48.966898+00:00', 'end': '2024-04-23 11:54:51'}
[2024-04-23T11:58:07.511+0000] {pipeline_eq.py:73} INFO - start to get objects in minio
[2024-04-23T11:58:07.512+0000] {logging_mixin.py:188} INFO - intervals is {'start': '2024-04-23 11:54:48.966898+00:00', 'end': '2024-04-23 11:54:51'}
[2024-04-23T11:58:29.401+0000] {taskinstance.py:2731} ERROR - Task failed with exception
Traceback (most recent call last):
  File "/home/yasmine/.local/share/virtualenvs/knowledge-base-siaap-WvBZnYs-/lib/python3.8/site-packages/airflow/models/taskinstance.py", line 444, in _execute_task
    result = _execute_callable(context=context, **execute_callable_kwargs)
  File "/home/yasmine/.local/share/virtualenvs/knowledge-base-siaap-WvBZnYs-/lib/python3.8/site-packages/airflow/models/taskinstance.py", line 414, in _execute_callable
    return execute_callable(context=context, **execute_callable_kwargs)
  File "/home/yasmine/.local/share/virtualenvs/knowledge-base-siaap-WvBZnYs-/lib/python3.8/site-packages/airflow/decorators/base.py", line 241, in execute
    return_value = super().execute(context)
  File "/home/yasmine/.local/share/virtualenvs/knowledge-base-siaap-WvBZnYs-/lib/python3.8/site-packages/airflow/operators/python.py", line 200, in execute
    return_value = self.execute_callable()
  File "/home/yasmine/.local/share/virtualenvs/knowledge-base-siaap-WvBZnYs-/lib/python3.8/site-packages/airflow/operators/python.py", line 217, in execute_callable
    return self.python_callable(*self.op_args, **self.op_kwargs)
  File "/home/yasmine/Documents/FREELANCE/knowledge-base-siaap/dags/kbs/custom_dags/pipeline_eq.py", line 80, in read_equipements
    good_objects = [obj.object_name for obj in objects if obj.object_name.lower().endswith(tuple(extensions)) and pd.to_datetime(intervals["start"], "%Y-%m-%d %H:%M:%S")<obj.last_modified <=  pd.to_datetime(intervals["end"], "%Y-%m-%d %H:%M:%S") ]
  File "/home/yasmine/Documents/FREELANCE/knowledge-base-siaap/dags/kbs/custom_dags/pipeline_eq.py", line 80, in <listcomp>
    good_objects = [obj.object_name for obj in objects if obj.object_name.lower().endswith(tuple(extensions)) and pd.to_datetime(intervals["start"], "%Y-%m-%d %H:%M:%S")<obj.last_modified <=  pd.to_datetime(intervals["end"], "%Y-%m-%d %H:%M:%S") ]
  File "/home/yasmine/.local/share/virtualenvs/knowledge-base-siaap-WvBZnYs-/lib/python3.8/site-packages/pandas/core/tools/datetimes.py", line 1084, in to_datetime
    result = convert_listlike(np.array([arg]), format)[0]
  File "/home/yasmine/.local/share/virtualenvs/knowledge-base-siaap-WvBZnYs-/lib/python3.8/site-packages/pandas/core/tools/datetimes.py", line 453, in _convert_listlike_datetimes
    return _array_strptime_with_fallback(arg, name, utc, format, exact, errors)
  File "/home/yasmine/.local/share/virtualenvs/knowledge-base-siaap-WvBZnYs-/lib/python3.8/site-packages/pandas/core/tools/datetimes.py", line 484, in _array_strptime_with_fallback
    result, timezones = array_strptime(arg, fmt, exact=exact, errors=errors, utc=utc)
  File "pandas/_libs/tslibs/strptime.pyx", line 191, in pandas._libs.tslibs.strptime.array_strptime
AssertionError
[2024-04-23T11:58:29.404+0000] {taskinstance.py:1149} INFO - Marking task as FAILED. dag_id=pipeline_eq, task_id=read_equipements, execution_date=20240423T115448, start_date=20240423T115805, end_date=20240423T115829
[2024-04-23T11:58:29.415+0000] {standard_task_runner.py:107} ERROR - Failed to execute job 283 for task read_equipements (; 112929)
[2024-04-23T11:58:29.423+0000] {local_task_job_runner.py:234} INFO - Task exited with return code 1
[2024-04-23T11:58:29.444+0000] {taskinstance.py:3312} INFO - 0 downstream tasks scheduled from follow-on schedule check
