[2024-04-23T12:42:42.641+0000] {taskinstance.py:1979} INFO - Dependencies all met for dep_context=non-requeueable deps ti=<TaskInstance: pipeline_eq.push_in_redis manual__2024-04-23T11:54:48.966898+00:00 map_index=4 [queued]>
[2024-04-23T12:42:42.647+0000] {taskinstance.py:1979} INFO - Dependencies all met for dep_context=requeueable deps ti=<TaskInstance: pipeline_eq.push_in_redis manual__2024-04-23T11:54:48.966898+00:00 map_index=4 [queued]>
[2024-04-23T12:42:42.647+0000] {taskinstance.py:2193} INFO - Starting attempt 1 of 1
[2024-04-23T12:42:42.657+0000] {taskinstance.py:2217} INFO - Executing <Mapped(_PythonDecoratedOperator): push_in_redis> on 2024-04-23 11:54:48.966898+00:00
[2024-04-23T12:42:42.662+0000] {standard_task_runner.py:60} INFO - Started process 151117 to run task
[2024-04-23T12:42:42.664+0000] {standard_task_runner.py:87} INFO - Running: ['airflow', 'tasks', 'run', 'pipeline_eq', 'push_in_redis', 'manual__2024-04-23T11:54:48.966898+00:00', '--job-id', '296', '--raw', '--subdir', 'DAGS_FOLDER/kbs/custom_dags/pipeline_eq.py', '--cfg-path', '/tmp/tmp4dpy4hw_', '--map-index', '4']
[2024-04-23T12:42:42.665+0000] {standard_task_runner.py:88} INFO - Job 296: Subtask push_in_redis
[2024-04-23T12:42:42.688+0000] {task_command.py:423} INFO - Running <TaskInstance: pipeline_eq.push_in_redis manual__2024-04-23T11:54:48.966898+00:00 map_index=4 [running]> on host datalab-yasmine
[2024-04-23T12:42:42.871+0000] {taskinstance.py:2513} INFO - Exporting env vars: AIRFLOW_CTX_DAG_OWNER='airflow' AIRFLOW_CTX_DAG_ID='pipeline_eq' AIRFLOW_CTX_TASK_ID='push_in_redis' AIRFLOW_CTX_EXECUTION_DATE='2024-04-23T11:54:48.966898+00:00' AIRFLOW_CTX_TRY_NUMBER='1' AIRFLOW_CTX_DAG_RUN_ID='manual__2024-04-23T11:54:48.966898+00:00'
[2024-04-23T12:42:42.871+0000] {pipeline_eq.py:90} INFO - start to push data in redis
[2024-04-23T12:42:45.361+0000] {connectionpool.py:874} WARNING - Retrying (Retry(total=4, connect=None, read=None, redirect=None, status=None)) after connection broken by 'RemoteDisconnected('Remote end closed connection without response')': /extracted?location=
[2024-04-23T12:42:46.909+0000] {taskinstance.py:2731} ERROR - Task failed with exception
Traceback (most recent call last):
  File "/home/yasmine/.local/share/virtualenvs/knowledge-base-siaap-WvBZnYs-/lib/python3.8/site-packages/airflow/models/taskinstance.py", line 444, in _execute_task
    result = _execute_callable(context=context, **execute_callable_kwargs)
  File "/home/yasmine/.local/share/virtualenvs/knowledge-base-siaap-WvBZnYs-/lib/python3.8/site-packages/airflow/models/taskinstance.py", line 414, in _execute_callable
    return execute_callable(context=context, **execute_callable_kwargs)
  File "/home/yasmine/.local/share/virtualenvs/knowledge-base-siaap-WvBZnYs-/lib/python3.8/site-packages/airflow/decorators/base.py", line 241, in execute
    return_value = super().execute(context)
  File "/home/yasmine/.local/share/virtualenvs/knowledge-base-siaap-WvBZnYs-/lib/python3.8/site-packages/airflow/operators/python.py", line 200, in execute
    return_value = self.execute_callable()
  File "/home/yasmine/.local/share/virtualenvs/knowledge-base-siaap-WvBZnYs-/lib/python3.8/site-packages/airflow/operators/python.py", line 217, in execute_callable
    return self.python_callable(*self.op_args, **self.op_kwargs)
  File "/home/yasmine/Documents/FREELANCE/knowledge-base-siaap/dags/kbs/custom_dags/pipeline_eq.py", line 94, in push_in_redis
    key = uuid.UUID()
  File "/home/yasmine/.pyenv/versions/3.8.16/lib/python3.8/uuid.py", line 165, in __init__
    raise TypeError('one of the hex, bytes, bytes_le, fields, '
TypeError: one of the hex, bytes, bytes_le, fields, or int arguments must be given
[2024-04-23T12:42:46.912+0000] {taskinstance.py:1149} INFO - Marking task as FAILED. dag_id=pipeline_eq, task_id=push_in_redis, map_index=4, execution_date=20240423T115448, start_date=20240423T124242, end_date=20240423T124246
[2024-04-23T12:42:46.920+0000] {standard_task_runner.py:107} ERROR - Failed to execute job 296 for task push_in_redis (one of the hex, bytes, bytes_le, fields, or int arguments must be given; 151117)
[2024-04-23T12:42:46.934+0000] {local_task_job_runner.py:234} INFO - Task exited with return code 1
[2024-04-23T12:42:46.941+0000] {taskinstance.py:3312} INFO - 0 downstream tasks scheduled from follow-on schedule check
